{
 "cells": [
  {
   "cell_type": "markdown",
   "metadata": {},
   "source": [
    "# [Exceptions](https://docs.python.org/3/library/exceptions.html#concrete-exceptions)\n",
    "When something goes wrong an exception is raised. For example, if you try to divide by zero, `ZeroDivisionError` is raised or if you try to access a nonexistent key in a dictionary, `KeyError` is raised.\n",
    "\n"
   ]
  },
  {
   "cell_type": "code",
   "execution_count": 2,
   "metadata": {},
   "outputs": [],
   "source": [
    "empty_dict = {} #Cuidado que esto es un diccionario\n",
    "#empty_dict['key']  # Uncomment to see the traceback. Da un KeyError porque no hay ninguna clave en ese diccionario"
   ]
  },
  {
   "cell_type": "markdown",
   "metadata": {},
   "source": [
    "## `try-except` structure \n",
    "If you know that a block of code can fail in some manner, you can use `try-except` structure to handle potential exceptions in a desired way."
   ]
  },
  {
   "cell_type": "code",
   "execution_count": 3,
   "metadata": {},
   "outputs": [
    {
     "name": "stdout",
     "output_type": "stream",
     "text": [
      "Uups, file: not_existing.txt not found\n",
      "Exception: [Errno 2] No such file or directory: 'not_existing.txt' was raised\n"
     ]
    }
   ],
   "source": [
    "# Let's try to open a file that does not exist\n",
    "file_name = 'not_existing.txt'\n",
    "\n",
    "try:\n",
    "    with open(file_name, 'r') as my_file:\n",
    "        print('File is successfully open')\n",
    "        \n",
    "except FileNotFoundError as e: #Limita el except a ese tipo de error en concreto. Además crea la variable 'e' con el nombre del error\n",
    "    print('Uups, file: {} not found'.format(file_name))\n",
    "    print('Exception: {} was raised'.format(e))"
   ]
  },
  {
   "cell_type": "markdown",
   "metadata": {},
   "source": [
    "If you don't know the type of exceptions that a code block can possibly raise, you can use `Exception` which catches all exceptions. In addition, you can have multiple `except` statements."
   ]
  },
  {
   "cell_type": "code",
   "execution_count": 14,
   "metadata": {},
   "outputs": [
    {
     "name": "stdout",
     "output_type": "stream",
     "text": [
      "result1: 1.0\n",
      "Exception: unsupported operand type(s) for /: 'int' and 'str'\n",
      "Tipo de error: <class 'TypeError'>\n",
      "result2: 0\n",
      "Can't divide by zero\n",
      "Tipo de error: <class 'ZeroDivisionError'>\n",
      "result3: 0\n"
     ]
    }
   ],
   "source": [
    "def calculate_division(var1, var2):\n",
    "    result = 0\n",
    "    \n",
    "    try:\n",
    "        result = var1 / var2\n",
    "    except ZeroDivisionError as ex1:\n",
    "        print(\"Can't divide by zero\")\n",
    "        print(\"Tipo de error: {}\". format (type(ex1))) #miro de qué tipo es el error\n",
    "    except Exception as ex2:\n",
    "        print('Exception: {}'.format(ex2))\n",
    "        print(\"Tipo de error: {}\". format (type(ex2))) #miro de qué tipo es el error\n",
    "\n",
    "    return result\n",
    "\n",
    "result1 = calculate_division(3, 3)\n",
    "print('result1: {}'.format(result1))\n",
    "\n",
    "result2 = calculate_division(3, '3')\n",
    "print('result2: {}'.format(result2))\n",
    "\n",
    "result3 = calculate_division(3, 0)\n",
    "print('result3: {}'.format(result3))"
   ]
  },
  {
   "cell_type": "markdown",
   "metadata": {},
   "source": [
    "`try-except` can be also in outer scope:"
   ]
  },
  {
   "cell_type": "code",
   "execution_count": 15,
   "metadata": {},
   "outputs": [
    {
     "name": "stdout",
     "output_type": "stream",
     "text": [
      "unsupported operand type(s) for /: 'int' and 'str'\n"
     ]
    }
   ],
   "source": [
    "def calculate_division(var1, var2):\n",
    "    return var1 / var2\n",
    "\n",
    "try:\n",
    "    result = calculate_division(3, '3')\n",
    "except Exception as e:\n",
    "    print(e)"
   ]
  },
  {
   "cell_type": "markdown",
   "metadata": {},
   "source": [
    "## The `else` Clause\n",
    "\n",
    "Using the `else` statement you can instruct a program to execute a certain block of code only in the absence of exceptions"
   ]
  },
  {
   "cell_type": "code",
   "execution_count": null,
   "metadata": {},
   "outputs": [],
   "source": [
    "try:\n",
    "    print('All ok')\n",
    "except:\n",
    "    pass #pass quiere decir que no haga nada\n",
    "else:\n",
    "    print('Executing the else caluse')"
   ]
  },
  {
   "cell_type": "code",
   "execution_count": null,
   "metadata": {},
   "outputs": [],
   "source": [
    "try:\n",
    "    print('Before Exception')\n",
    "    x = 3 / 0\n",
    "except ZeroDivisionError:\n",
    "    pass\n",
    "else:\n",
    "    print('Executing the else caluse')\n",
    "\n",
    "print('After block')"
   ]
  },
  {
   "cell_type": "markdown",
   "metadata": {},
   "source": [
    "## Cleaning up after using `finally`\n",
    "\n",
    "Imagine that you always had to implement some sort of action to clean up after executing your code. Python enables you to do using the `finally` clause."
   ]
  },
  {
   "cell_type": "code",
   "execution_count": null,
   "metadata": {},
   "outputs": [],
   "source": [
    "try:\n",
    "    print('Before Exception')\n",
    "    x = 3 / 0\n",
    "except ZeroDivisionError:\n",
    "    print('Inside Exception')\n",
    "    pass\n",
    "else:\n",
    "    print('Executing the else clause')\n",
    "finally:\n",
    "    print('Clean up')\n",
    "\n",
    "print('After block')"
   ]
  },
  {
   "cell_type": "markdown",
   "metadata": {},
   "source": [
    "## Creating your custom exceptions\n",
    "In your own applications, you can use custom exceptions for signaling users about errors which occur during your application run time.  "
   ]
  },
  {
   "cell_type": "code",
   "execution_count": null,
   "metadata": {},
   "outputs": [],
   "source": [
    "import math\n",
    "\n",
    "# Define your own exception\n",
    "class NegativeNumbersNotSupported(Exception):\n",
    "    pass\n",
    "\n",
    "# Dummy example how to use your custom exception\n",
    "def secret_calculation(number1, number2):\n",
    "    if number1 < 0 or number2 < 0:\n",
    "        msg = 'Negative number in at least one of the parameters: {}, {}'.format(\n",
    "            number1, number2)\n",
    "        raise NegativeNumbersNotSupported(msg)\n",
    "\n",
    "    return math.sqrt(number1) + math.sqrt(number2)\n",
    "\n",
    "# Uncomment to see the traceback\n",
    "# result = secret_calculation(-1, 1)"
   ]
  }
 ],
 "metadata": {
  "kernelspec": {
   "display_name": "Python 3",
   "language": "python",
   "name": "python3"
  },
  "language_info": {
   "codemirror_mode": {
    "name": "ipython",
    "version": 3
   },
   "file_extension": ".py",
   "mimetype": "text/x-python",
   "name": "python",
   "nbconvert_exporter": "python",
   "pygments_lexer": "ipython3",
   "version": "3.11.2"
  }
 },
 "nbformat": 4,
 "nbformat_minor": 0
}
